Traceback (most recent call last):
  File "/root/project/bot_bulder/bot_builder/apps/worker/management/commands/new_worker.py", line 115, in worker
    message_text = serialized_data['message']['text']
KeyError: 'text'

During handling of the above exception, another exception occurred:

Traceback (most recent call last):
  File "/root/project/bot_bulder/bot_builder/manage.py", line 22, in <module>
    main()
  File "/root/project/bot_bulder/bot_builder/manage.py", line 18, in main
    execute_from_command_line(sys.argv)
  File "/root/project/venv/lib/python3.10/site-packages/django/core/management/__init__.py", line 442, in execute_from_command_line
    utility.execute()
  File "/root/project/venv/lib/python3.10/site-packages/django/core/management/__init__.py", line 436, in execute
    self.fetch_command(subcommand).run_from_argv(self.argv)
  File "/root/project/venv/lib/python3.10/site-packages/django/core/management/__init__.py", line 275, in fetch_command
    klass = load_command_class(app_name, subcommand)
  File "/root/project/venv/lib/python3.10/site-packages/django/core/management/__init__.py", line 48, in load_command_class
    module = import_module("%s.management.commands.%s" % (app_name, name))
  File "/usr/lib/python3.10/importlib/__init__.py", line 126, in import_module
    return _bootstrap._gcd_import(name[level:], package, level)
  File "<frozen importlib._bootstrap>", line 1050, in _gcd_import
  File "<frozen importlib._bootstrap>", line 1027, in _find_and_load
  File "<frozen importlib._bootstrap>", line 1006, in _find_and_load_unlocked
  File "<frozen importlib._bootstrap>", line 688, in _load_unlocked
  File "<frozen importlib._bootstrap_external>", line 883, in exec_module
  File "<frozen importlib._bootstrap>", line 241, in _call_with_frames_removed
  File "/root/project/bot_bulder/bot_builder/apps/worker/management/commands/new_worker.py", line 13, in <module>
    class Command(BaseCommand):
  File "/root/project/bot_bulder/bot_builder/apps/worker/management/commands/new_worker.py", line 172, in Command
    worker(bot)
  File "/root/project/bot_bulder/bot_builder/apps/worker/management/commands/new_worker.py", line 159, in worker
    state=Bot_Message.objects.get(current_state=user.state)
  File "/root/project/venv/lib/python3.10/site-packages/django/db/models/manager.py", line 87, in manager_method
    return getattr(self.get_queryset(), name)(*args, **kwargs)
  File "/root/project/venv/lib/python3.10/site-packages/django/db/models/query.py", line 649, in get
    raise self.model.DoesNotExist(
apps.bot.models.Bot_Message.DoesNotExist: Bot_Message matching query does not exist.
Traceback (most recent call last):
  File "/root/project/bot_bulder/bot_builder/apps/worker/management/commands/new_worker.py", line 115, in worker
    message_text = serialized_data['message']['text']
KeyError: 'text'

During handling of the above exception, another exception occurred:

Traceback (most recent call last):
  File "/root/project/bot_bulder/bot_builder/manage.py", line 22, in <module>
    main()
  File "/root/project/bot_bulder/bot_builder/manage.py", line 18, in main
    execute_from_command_line(sys.argv)
  File "/root/project/venv/lib/python3.10/site-packages/django/core/management/__init__.py", line 442, in execute_from_command_line
    utility.execute()
  File "/root/project/venv/lib/python3.10/site-packages/django/core/management/__init__.py", line 436, in execute
    self.fetch_command(subcommand).run_from_argv(self.argv)
  File "/root/project/venv/lib/python3.10/site-packages/django/core/management/__init__.py", line 275, in fetch_command
    klass = load_command_class(app_name, subcommand)
  File "/root/project/venv/lib/python3.10/site-packages/django/core/management/__init__.py", line 48, in load_command_class
    module = import_module("%s.management.commands.%s" % (app_name, name))
  File "/usr/lib/python3.10/importlib/__init__.py", line 126, in import_module
    return _bootstrap._gcd_import(name[level:], package, level)
  File "<frozen importlib._bootstrap>", line 1050, in _gcd_import
  File "<frozen importlib._bootstrap>", line 1027, in _find_and_load
  File "<frozen importlib._bootstrap>", line 1006, in _find_and_load_unlocked
  File "<frozen importlib._bootstrap>", line 688, in _load_unlocked
  File "<frozen importlib._bootstrap_external>", line 883, in exec_module
  File "<frozen importlib._bootstrap>", line 241, in _call_with_frames_removed
  File "/root/project/bot_bulder/bot_builder/apps/worker/management/commands/new_worker.py", line 13, in <module>
    class Command(BaseCommand):
  File "/root/project/bot_bulder/bot_builder/apps/worker/management/commands/new_worker.py", line 172, in Command
    worker(bot)
  File "/root/project/bot_bulder/bot_builder/apps/worker/management/commands/new_worker.py", line 159, in worker
    state=Bot_Message.objects.get(current_state=user.state)
  File "/root/project/venv/lib/python3.10/site-packages/django/db/models/manager.py", line 87, in manager_method
    return getattr(self.get_queryset(), name)(*args, **kwargs)
  File "/root/project/venv/lib/python3.10/site-packages/django/db/models/query.py", line 649, in get
    raise self.model.DoesNotExist(
apps.bot.models.Bot_Message.DoesNotExist: Bot_Message matching query does not exist.
Traceback (most recent call last):
  File "/root/project/bot_bulder/bot_builder/apps/worker/management/commands/new_worker.py", line 115, in worker
    message_text = serialized_data['message']['text']
KeyError: 'text'

During handling of the above exception, another exception occurred:

Traceback (most recent call last):
  File "/root/project/bot_bulder/bot_builder/manage.py", line 22, in <module>
    main()
  File "/root/project/bot_bulder/bot_builder/manage.py", line 18, in main
    execute_from_command_line(sys.argv)
  File "/root/project/venv/lib/python3.10/site-packages/django/core/management/__init__.py", line 442, in execute_from_command_line
    utility.execute()
  File "/root/project/venv/lib/python3.10/site-packages/django/core/management/__init__.py", line 436, in execute
    self.fetch_command(subcommand).run_from_argv(self.argv)
  File "/root/project/venv/lib/python3.10/site-packages/django/core/management/__init__.py", line 275, in fetch_command
    klass = load_command_class(app_name, subcommand)
  File "/root/project/venv/lib/python3.10/site-packages/django/core/management/__init__.py", line 48, in load_command_class
    module = import_module("%s.management.commands.%s" % (app_name, name))
  File "/usr/lib/python3.10/importlib/__init__.py", line 126, in import_module
    return _bootstrap._gcd_import(name[level:], package, level)
  File "<frozen importlib._bootstrap>", line 1050, in _gcd_import
  File "<frozen importlib._bootstrap>", line 1027, in _find_and_load
  File "<frozen importlib._bootstrap>", line 1006, in _find_and_load_unlocked
  File "<frozen importlib._bootstrap>", line 688, in _load_unlocked
  File "<frozen importlib._bootstrap_external>", line 883, in exec_module
  File "<frozen importlib._bootstrap>", line 241, in _call_with_frames_removed
  File "/root/project/bot_bulder/bot_builder/apps/worker/management/commands/new_worker.py", line 13, in <module>
    class Command(BaseCommand):
  File "/root/project/bot_bulder/bot_builder/apps/worker/management/commands/new_worker.py", line 172, in Command
    worker(bot)
  File "/root/project/bot_bulder/bot_builder/apps/worker/management/commands/new_worker.py", line 159, in worker
    state=Bot_Message.objects.get(current_state=user.state)
  File "/root/project/venv/lib/python3.10/site-packages/django/db/models/manager.py", line 87, in manager_method
    return getattr(self.get_queryset(), name)(*args, **kwargs)
  File "/root/project/venv/lib/python3.10/site-packages/django/db/models/query.py", line 649, in get
    raise self.model.DoesNotExist(
apps.bot.models.Bot_Message.DoesNotExist: Bot_Message matching query does not exist.
Traceback (most recent call last):
  File "/root/project/bot_bulder/bot_builder/apps/worker/management/commands/new_worker.py", line 115, in worker
    message_text = serialized_data['message']['text']
KeyError: 'text'

During handling of the above exception, another exception occurred:

Traceback (most recent call last):
  File "/root/project/bot_bulder/bot_builder/manage.py", line 22, in <module>
    main()
  File "/root/project/bot_bulder/bot_builder/manage.py", line 18, in main
    execute_from_command_line(sys.argv)
  File "/root/project/venv/lib/python3.10/site-packages/django/core/management/__init__.py", line 442, in execute_from_command_line
    utility.execute()
  File "/root/project/venv/lib/python3.10/site-packages/django/core/management/__init__.py", line 436, in execute
    self.fetch_command(subcommand).run_from_argv(self.argv)
  File "/root/project/venv/lib/python3.10/site-packages/django/core/management/__init__.py", line 275, in fetch_command
    klass = load_command_class(app_name, subcommand)
  File "/root/project/venv/lib/python3.10/site-packages/django/core/management/__init__.py", line 48, in load_command_class
    module = import_module("%s.management.commands.%s" % (app_name, name))
  File "/usr/lib/python3.10/importlib/__init__.py", line 126, in import_module
    return _bootstrap._gcd_import(name[level:], package, level)
  File "<frozen importlib._bootstrap>", line 1050, in _gcd_import
  File "<frozen importlib._bootstrap>", line 1027, in _find_and_load
  File "<frozen importlib._bootstrap>", line 1006, in _find_and_load_unlocked
  File "<frozen importlib._bootstrap>", line 688, in _load_unlocked
  File "<frozen importlib._bootstrap_external>", line 883, in exec_module
  File "<frozen importlib._bootstrap>", line 241, in _call_with_frames_removed
  File "/root/project/bot_bulder/bot_builder/apps/worker/management/commands/new_worker.py", line 13, in <module>
    class Command(BaseCommand):
  File "/root/project/bot_bulder/bot_builder/apps/worker/management/commands/new_worker.py", line 172, in Command
    worker(bot)
  File "/root/project/bot_bulder/bot_builder/apps/worker/management/commands/new_worker.py", line 159, in worker
    state=Bot_Message.objects.get(current_state=user.state)
  File "/root/project/venv/lib/python3.10/site-packages/django/db/models/manager.py", line 87, in manager_method
    return getattr(self.get_queryset(), name)(*args, **kwargs)
  File "/root/project/venv/lib/python3.10/site-packages/django/db/models/query.py", line 649, in get
    raise self.model.DoesNotExist(
apps.bot.models.Bot_Message.DoesNotExist: Bot_Message matching query does not exist.
Traceback (most recent call last):
  File "/root/project/bot_bulder/bot_builder/apps/worker/management/commands/new_worker.py", line 115, in worker
    message_text = serialized_data['message']['text']
KeyError: 'text'

During handling of the above exception, another exception occurred:

Traceback (most recent call last):
  File "/root/project/bot_bulder/bot_builder/manage.py", line 22, in <module>
    main()
  File "/root/project/bot_bulder/bot_builder/manage.py", line 18, in main
    execute_from_command_line(sys.argv)
  File "/root/project/venv/lib/python3.10/site-packages/django/core/management/__init__.py", line 442, in execute_from_command_line
    utility.execute()
  File "/root/project/venv/lib/python3.10/site-packages/django/core/management/__init__.py", line 436, in execute
    self.fetch_command(subcommand).run_from_argv(self.argv)
  File "/root/project/venv/lib/python3.10/site-packages/django/core/management/__init__.py", line 275, in fetch_command
    klass = load_command_class(app_name, subcommand)
  File "/root/project/venv/lib/python3.10/site-packages/django/core/management/__init__.py", line 48, in load_command_class
    module = import_module("%s.management.commands.%s" % (app_name, name))
  File "/usr/lib/python3.10/importlib/__init__.py", line 126, in import_module
    return _bootstrap._gcd_import(name[level:], package, level)
  File "<frozen importlib._bootstrap>", line 1050, in _gcd_import
  File "<frozen importlib._bootstrap>", line 1027, in _find_and_load
  File "<frozen importlib._bootstrap>", line 1006, in _find_and_load_unlocked
  File "<frozen importlib._bootstrap>", line 688, in _load_unlocked
  File "<frozen importlib._bootstrap_external>", line 883, in exec_module
  File "<frozen importlib._bootstrap>", line 241, in _call_with_frames_removed
  File "/root/project/bot_bulder/bot_builder/apps/worker/management/commands/new_worker.py", line 13, in <module>
    class Command(BaseCommand):
  File "/root/project/bot_bulder/bot_builder/apps/worker/management/commands/new_worker.py", line 172, in Command
    worker(bot)
  File "/root/project/bot_bulder/bot_builder/apps/worker/management/commands/new_worker.py", line 159, in worker
    state=Bot_Message.objects.get(current_state=user.state)
  File "/root/project/venv/lib/python3.10/site-packages/django/db/models/manager.py", line 87, in manager_method
    return getattr(self.get_queryset(), name)(*args, **kwargs)
  File "/root/project/venv/lib/python3.10/site-packages/django/db/models/query.py", line 649, in get
    raise self.model.DoesNotExist(
apps.bot.models.Bot_Message.DoesNotExist: Bot_Message matching query does not exist.
Traceback (most recent call last):
  File "/root/project/bot_bulder/bot_builder/apps/worker/management/commands/new_worker.py", line 115, in worker
    message_text = serialized_data['message']['text']
KeyError: 'text'

During handling of the above exception, another exception occurred:

Traceback (most recent call last):
  File "/root/project/bot_bulder/bot_builder/manage.py", line 22, in <module>
    main()
  File "/root/project/bot_bulder/bot_builder/manage.py", line 18, in main
    execute_from_command_line(sys.argv)
  File "/root/project/venv/lib/python3.10/site-packages/django/core/management/__init__.py", line 442, in execute_from_command_line
    utility.execute()
  File "/root/project/venv/lib/python3.10/site-packages/django/core/management/__init__.py", line 436, in execute
    self.fetch_command(subcommand).run_from_argv(self.argv)
  File "/root/project/venv/lib/python3.10/site-packages/django/core/management/__init__.py", line 275, in fetch_command
    klass = load_command_class(app_name, subcommand)
  File "/root/project/venv/lib/python3.10/site-packages/django/core/management/__init__.py", line 48, in load_command_class
    module = import_module("%s.management.commands.%s" % (app_name, name))
  File "/usr/lib/python3.10/importlib/__init__.py", line 126, in import_module
    return _bootstrap._gcd_import(name[level:], package, level)
  File "<frozen importlib._bootstrap>", line 1050, in _gcd_import
  File "<frozen importlib._bootstrap>", line 1027, in _find_and_load
  File "<frozen importlib._bootstrap>", line 1006, in _find_and_load_unlocked
  File "<frozen importlib._bootstrap>", line 688, in _load_unlocked
  File "<frozen importlib._bootstrap_external>", line 883, in exec_module
  File "<frozen importlib._bootstrap>", line 241, in _call_with_frames_removed
  File "/root/project/bot_bulder/bot_builder/apps/worker/management/commands/new_worker.py", line 13, in <module>
    class Command(BaseCommand):
  File "/root/project/bot_bulder/bot_builder/apps/worker/management/commands/new_worker.py", line 172, in Command
    worker(bot)
  File "/root/project/bot_bulder/bot_builder/apps/worker/management/commands/new_worker.py", line 159, in worker
    state=Bot_Message.objects.get(current_state=user.state)
  File "/root/project/venv/lib/python3.10/site-packages/django/db/models/manager.py", line 87, in manager_method
    return getattr(self.get_queryset(), name)(*args, **kwargs)
  File "/root/project/venv/lib/python3.10/site-packages/django/db/models/query.py", line 649, in get
    raise self.model.DoesNotExist(
apps.bot.models.Bot_Message.DoesNotExist: Bot_Message matching query does not exist.
Traceback (most recent call last):
  File "/root/project/bot_bulder/bot_builder/apps/worker/management/commands/new_worker.py", line 115, in worker
    message_text = serialized_data['message']['text']
KeyError: 'text'

During handling of the above exception, another exception occurred:

Traceback (most recent call last):
  File "/root/project/bot_bulder/bot_builder/manage.py", line 22, in <module>
    main()
  File "/root/project/bot_bulder/bot_builder/manage.py", line 18, in main
    execute_from_command_line(sys.argv)
  File "/root/project/venv/lib/python3.10/site-packages/django/core/management/__init__.py", line 442, in execute_from_command_line
    utility.execute()
  File "/root/project/venv/lib/python3.10/site-packages/django/core/management/__init__.py", line 436, in execute
    self.fetch_command(subcommand).run_from_argv(self.argv)
  File "/root/project/venv/lib/python3.10/site-packages/django/core/management/__init__.py", line 275, in fetch_command
    klass = load_command_class(app_name, subcommand)
  File "/root/project/venv/lib/python3.10/site-packages/django/core/management/__init__.py", line 48, in load_command_class
    module = import_module("%s.management.commands.%s" % (app_name, name))
  File "/usr/lib/python3.10/importlib/__init__.py", line 126, in import_module
    return _bootstrap._gcd_import(name[level:], package, level)
  File "<frozen importlib._bootstrap>", line 1050, in _gcd_import
  File "<frozen importlib._bootstrap>", line 1027, in _find_and_load
  File "<frozen importlib._bootstrap>", line 1006, in _find_and_load_unlocked
  File "<frozen importlib._bootstrap>", line 688, in _load_unlocked
  File "<frozen importlib._bootstrap_external>", line 883, in exec_module
  File "<frozen importlib._bootstrap>", line 241, in _call_with_frames_removed
  File "/root/project/bot_bulder/bot_builder/apps/worker/management/commands/new_worker.py", line 13, in <module>
    class Command(BaseCommand):
  File "/root/project/bot_bulder/bot_builder/apps/worker/management/commands/new_worker.py", line 172, in Command
    worker(bot)
  File "/root/project/bot_bulder/bot_builder/apps/worker/management/commands/new_worker.py", line 159, in worker
    state=Bot_Message.objects.get(current_state=user.state)
  File "/root/project/venv/lib/python3.10/site-packages/django/db/models/manager.py", line 87, in manager_method
    return getattr(self.get_queryset(), name)(*args, **kwargs)
  File "/root/project/venv/lib/python3.10/site-packages/django/db/models/query.py", line 649, in get
    raise self.model.DoesNotExist(
apps.bot.models.Bot_Message.DoesNotExist: Bot_Message matching query does not exist.
Traceback (most recent call last):
  File "/root/project/bot_bulder/bot_builder/apps/worker/management/commands/new_worker.py", line 115, in worker
    message_text = serialized_data['message']['text']
KeyError: 'text'

During handling of the above exception, another exception occurred:

Traceback (most recent call last):
  File "/root/project/bot_bulder/bot_builder/manage.py", line 22, in <module>
    main()
  File "/root/project/bot_bulder/bot_builder/manage.py", line 18, in main
    execute_from_command_line(sys.argv)
  File "/root/project/venv/lib/python3.10/site-packages/django/core/management/__init__.py", line 442, in execute_from_command_line
    utility.execute()
  File "/root/project/venv/lib/python3.10/site-packages/django/core/management/__init__.py", line 436, in execute
    self.fetch_command(subcommand).run_from_argv(self.argv)
  File "/root/project/venv/lib/python3.10/site-packages/django/core/management/__init__.py", line 275, in fetch_command
    klass = load_command_class(app_name, subcommand)
  File "/root/project/venv/lib/python3.10/site-packages/django/core/management/__init__.py", line 48, in load_command_class
    module = import_module("%s.management.commands.%s" % (app_name, name))
  File "/usr/lib/python3.10/importlib/__init__.py", line 126, in import_module
    return _bootstrap._gcd_import(name[level:], package, level)
  File "<frozen importlib._bootstrap>", line 1050, in _gcd_import
  File "<frozen importlib._bootstrap>", line 1027, in _find_and_load
  File "<frozen importlib._bootstrap>", line 1006, in _find_and_load_unlocked
  File "<frozen importlib._bootstrap>", line 688, in _load_unlocked
  File "<frozen importlib._bootstrap_external>", line 883, in exec_module
  File "<frozen importlib._bootstrap>", line 241, in _call_with_frames_removed
  File "/root/project/bot_bulder/bot_builder/apps/worker/management/commands/new_worker.py", line 13, in <module>
    class Command(BaseCommand):
  File "/root/project/bot_bulder/bot_builder/apps/worker/management/commands/new_worker.py", line 172, in Command
    worker(bot)
  File "/root/project/bot_bulder/bot_builder/apps/worker/management/commands/new_worker.py", line 159, in worker
    state=Bot_Message.objects.get(current_state=user.state)
  File "/root/project/venv/lib/python3.10/site-packages/django/db/models/manager.py", line 87, in manager_method
    return getattr(self.get_queryset(), name)(*args, **kwargs)
  File "/root/project/venv/lib/python3.10/site-packages/django/db/models/query.py", line 649, in get
    raise self.model.DoesNotExist(
apps.bot.models.Bot_Message.DoesNotExist: Bot_Message matching query does not exist.
Traceback (most recent call last):
  File "/root/project/bot_bulder/bot_builder/apps/worker/management/commands/new_worker.py", line 115, in worker
    message_text = serialized_data['message']['text']
KeyError: 'text'

During handling of the above exception, another exception occurred:

Traceback (most recent call last):
  File "/root/project/bot_bulder/bot_builder/manage.py", line 22, in <module>
    main()
  File "/root/project/bot_bulder/bot_builder/manage.py", line 18, in main
    execute_from_command_line(sys.argv)
  File "/root/project/venv/lib/python3.10/site-packages/django/core/management/__init__.py", line 442, in execute_from_command_line
    utility.execute()
  File "/root/project/venv/lib/python3.10/site-packages/django/core/management/__init__.py", line 436, in execute
    self.fetch_command(subcommand).run_from_argv(self.argv)
  File "/root/project/venv/lib/python3.10/site-packages/django/core/management/__init__.py", line 275, in fetch_command
    klass = load_command_class(app_name, subcommand)
  File "/root/project/venv/lib/python3.10/site-packages/django/core/management/__init__.py", line 48, in load_command_class
    module = import_module("%s.management.commands.%s" % (app_name, name))
  File "/usr/lib/python3.10/importlib/__init__.py", line 126, in import_module
    return _bootstrap._gcd_import(name[level:], package, level)
  File "<frozen importlib._bootstrap>", line 1050, in _gcd_import
  File "<frozen importlib._bootstrap>", line 1027, in _find_and_load
  File "<frozen importlib._bootstrap>", line 1006, in _find_and_load_unlocked
  File "<frozen importlib._bootstrap>", line 688, in _load_unlocked
  File "<frozen importlib._bootstrap_external>", line 883, in exec_module
  File "<frozen importlib._bootstrap>", line 241, in _call_with_frames_removed
  File "/root/project/bot_bulder/bot_builder/apps/worker/management/commands/new_worker.py", line 13, in <module>
    class Command(BaseCommand):
  File "/root/project/bot_bulder/bot_builder/apps/worker/management/commands/new_worker.py", line 172, in Command
    worker(bot)
  File "/root/project/bot_bulder/bot_builder/apps/worker/management/commands/new_worker.py", line 159, in worker
    state=Bot_Message.objects.get(current_state=user.state)
  File "/root/project/venv/lib/python3.10/site-packages/django/db/models/manager.py", line 87, in manager_method
    return getattr(self.get_queryset(), name)(*args, **kwargs)
  File "/root/project/venv/lib/python3.10/site-packages/django/db/models/query.py", line 649, in get
    raise self.model.DoesNotExist(
apps.bot.models.Bot_Message.DoesNotExist: Bot_Message matching query does not exist.
Traceback (most recent call last):
  File "/root/project/bot_bulder/bot_builder/apps/worker/management/commands/new_worker.py", line 115, in worker
    message_text = serialized_data['message']['text']
KeyError: 'text'

During handling of the above exception, another exception occurred:

Traceback (most recent call last):
  File "/root/project/bot_bulder/bot_builder/manage.py", line 22, in <module>
    main()
  File "/root/project/bot_bulder/bot_builder/manage.py", line 18, in main
    execute_from_command_line(sys.argv)
  File "/root/project/venv/lib/python3.10/site-packages/django/core/management/__init__.py", line 442, in execute_from_command_line
    utility.execute()
  File "/root/project/venv/lib/python3.10/site-packages/django/core/management/__init__.py", line 436, in execute
    self.fetch_command(subcommand).run_from_argv(self.argv)
  File "/root/project/venv/lib/python3.10/site-packages/django/core/management/__init__.py", line 275, in fetch_command
    klass = load_command_class(app_name, subcommand)
  File "/root/project/venv/lib/python3.10/site-packages/django/core/management/__init__.py", line 48, in load_command_class
    module = import_module("%s.management.commands.%s" % (app_name, name))
  File "/usr/lib/python3.10/importlib/__init__.py", line 126, in import_module
    return _bootstrap._gcd_import(name[level:], package, level)
  File "<frozen importlib._bootstrap>", line 1050, in _gcd_import
  File "<frozen importlib._bootstrap>", line 1027, in _find_and_load
  File "<frozen importlib._bootstrap>", line 1006, in _find_and_load_unlocked
  File "<frozen importlib._bootstrap>", line 688, in _load_unlocked
  File "<frozen importlib._bootstrap_external>", line 883, in exec_module
  File "<frozen importlib._bootstrap>", line 241, in _call_with_frames_removed
  File "/root/project/bot_bulder/bot_builder/apps/worker/management/commands/new_worker.py", line 13, in <module>
    class Command(BaseCommand):
  File "/root/project/bot_bulder/bot_builder/apps/worker/management/commands/new_worker.py", line 172, in Command
    worker(bot)
  File "/root/project/bot_bulder/bot_builder/apps/worker/management/commands/new_worker.py", line 159, in worker
    state=Bot_Message.objects.get(current_state=user.state)
  File "/root/project/venv/lib/python3.10/site-packages/django/db/models/manager.py", line 87, in manager_method
    return getattr(self.get_queryset(), name)(*args, **kwargs)
  File "/root/project/venv/lib/python3.10/site-packages/django/db/models/query.py", line 649, in get
    raise self.model.DoesNotExist(
apps.bot.models.Bot_Message.DoesNotExist: Bot_Message matching query does not exist.
Traceback (most recent call last):
  File "/root/project/bot_bulder/bot_builder/apps/worker/management/commands/new_worker.py", line 115, in worker
    message_text = serialized_data['message']['text']
KeyError: 'text'

During handling of the above exception, another exception occurred:

Traceback (most recent call last):
  File "/root/project/bot_bulder/bot_builder/manage.py", line 22, in <module>
    main()
  File "/root/project/bot_bulder/bot_builder/manage.py", line 18, in main
    execute_from_command_line(sys.argv)
  File "/root/project/venv/lib/python3.10/site-packages/django/core/management/__init__.py", line 442, in execute_from_command_line
    utility.execute()
  File "/root/project/venv/lib/python3.10/site-packages/django/core/management/__init__.py", line 436, in execute
    self.fetch_command(subcommand).run_from_argv(self.argv)
  File "/root/project/venv/lib/python3.10/site-packages/django/core/management/__init__.py", line 275, in fetch_command
    klass = load_command_class(app_name, subcommand)
  File "/root/project/venv/lib/python3.10/site-packages/django/core/management/__init__.py", line 48, in load_command_class
    module = import_module("%s.management.commands.%s" % (app_name, name))
  File "/usr/lib/python3.10/importlib/__init__.py", line 126, in import_module
    return _bootstrap._gcd_import(name[level:], package, level)
  File "<frozen importlib._bootstrap>", line 1050, in _gcd_import
  File "<frozen importlib._bootstrap>", line 1027, in _find_and_load
  File "<frozen importlib._bootstrap>", line 1006, in _find_and_load_unlocked
  File "<frozen importlib._bootstrap>", line 688, in _load_unlocked
  File "<frozen importlib._bootstrap_external>", line 883, in exec_module
  File "<frozen importlib._bootstrap>", line 241, in _call_with_frames_removed
  File "/root/project/bot_bulder/bot_builder/apps/worker/management/commands/new_worker.py", line 13, in <module>
    class Command(BaseCommand):
  File "/root/project/bot_bulder/bot_builder/apps/worker/management/commands/new_worker.py", line 172, in Command
    worker(bot)
  File "/root/project/bot_bulder/bot_builder/apps/worker/management/commands/new_worker.py", line 159, in worker
    state=Bot_Message.objects.get(current_state=user.state)
  File "/root/project/venv/lib/python3.10/site-packages/django/db/models/manager.py", line 87, in manager_method
    return getattr(self.get_queryset(), name)(*args, **kwargs)
  File "/root/project/venv/lib/python3.10/site-packages/django/db/models/query.py", line 649, in get
    raise self.model.DoesNotExist(
apps.bot.models.Bot_Message.DoesNotExist: Bot_Message matching query does not exist.
Traceback (most recent call last):
  File "/root/project/bot_bulder/bot_builder/apps/worker/management/commands/new_worker.py", line 115, in worker
    message_text = serialized_data['message']['text']
KeyError: 'text'

During handling of the above exception, another exception occurred:

Traceback (most recent call last):
  File "/root/project/bot_bulder/bot_builder/manage.py", line 22, in <module>
    main()
  File "/root/project/bot_bulder/bot_builder/manage.py", line 18, in main
    execute_from_command_line(sys.argv)
  File "/root/project/venv/lib/python3.10/site-packages/django/core/management/__init__.py", line 442, in execute_from_command_line
    utility.execute()
  File "/root/project/venv/lib/python3.10/site-packages/django/core/management/__init__.py", line 436, in execute
    self.fetch_command(subcommand).run_from_argv(self.argv)
  File "/root/project/venv/lib/python3.10/site-packages/django/core/management/__init__.py", line 275, in fetch_command
    klass = load_command_class(app_name, subcommand)
  File "/root/project/venv/lib/python3.10/site-packages/django/core/management/__init__.py", line 48, in load_command_class
    module = import_module("%s.management.commands.%s" % (app_name, name))
  File "/usr/lib/python3.10/importlib/__init__.py", line 126, in import_module
    return _bootstrap._gcd_import(name[level:], package, level)
  File "<frozen importlib._bootstrap>", line 1050, in _gcd_import
  File "<frozen importlib._bootstrap>", line 1027, in _find_and_load
  File "<frozen importlib._bootstrap>", line 1006, in _find_and_load_unlocked
  File "<frozen importlib._bootstrap>", line 688, in _load_unlocked
  File "<frozen importlib._bootstrap_external>", line 883, in exec_module
  File "<frozen importlib._bootstrap>", line 241, in _call_with_frames_removed
  File "/root/project/bot_bulder/bot_builder/apps/worker/management/commands/new_worker.py", line 13, in <module>
    class Command(BaseCommand):
  File "/root/project/bot_bulder/bot_builder/apps/worker/management/commands/new_worker.py", line 172, in Command
    worker(bot)
  File "/root/project/bot_bulder/bot_builder/apps/worker/management/commands/new_worker.py", line 159, in worker
    state=Bot_Message.objects.get(current_state=user.state)
  File "/root/project/venv/lib/python3.10/site-packages/django/db/models/manager.py", line 87, in manager_method
    return getattr(self.get_queryset(), name)(*args, **kwargs)
  File "/root/project/venv/lib/python3.10/site-packages/django/db/models/query.py", line 649, in get
    raise self.model.DoesNotExist(
apps.bot.models.Bot_Message.DoesNotExist: Bot_Message matching query does not exist.
Traceback (most recent call last):
  File "/root/project/bot_bulder/bot_builder/apps/worker/management/commands/new_worker.py", line 115, in worker
    message_text = serialized_data['message']['text']
KeyError: 'text'

During handling of the above exception, another exception occurred:

Traceback (most recent call last):
  File "/root/project/bot_bulder/bot_builder/manage.py", line 22, in <module>
    main()
  File "/root/project/bot_bulder/bot_builder/manage.py", line 18, in main
    execute_from_command_line(sys.argv)
  File "/root/project/venv/lib/python3.10/site-packages/django/core/management/__init__.py", line 442, in execute_from_command_line
    utility.execute()
  File "/root/project/venv/lib/python3.10/site-packages/django/core/management/__init__.py", line 436, in execute
    self.fetch_command(subcommand).run_from_argv(self.argv)
  File "/root/project/venv/lib/python3.10/site-packages/django/core/management/__init__.py", line 275, in fetch_command
    klass = load_command_class(app_name, subcommand)
  File "/root/project/venv/lib/python3.10/site-packages/django/core/management/__init__.py", line 48, in load_command_class
    module = import_module("%s.management.commands.%s" % (app_name, name))
  File "/usr/lib/python3.10/importlib/__init__.py", line 126, in import_module
    return _bootstrap._gcd_import(name[level:], package, level)
  File "<frozen importlib._bootstrap>", line 1050, in _gcd_import
  File "<frozen importlib._bootstrap>", line 1027, in _find_and_load
  File "<frozen importlib._bootstrap>", line 1006, in _find_and_load_unlocked
  File "<frozen importlib._bootstrap>", line 688, in _load_unlocked
  File "<frozen importlib._bootstrap_external>", line 883, in exec_module
  File "<frozen importlib._bootstrap>", line 241, in _call_with_frames_removed
  File "/root/project/bot_bulder/bot_builder/apps/worker/management/commands/new_worker.py", line 13, in <module>
    class Command(BaseCommand):
  File "/root/project/bot_bulder/bot_builder/apps/worker/management/commands/new_worker.py", line 172, in Command
    worker(bot)
  File "/root/project/bot_bulder/bot_builder/apps/worker/management/commands/new_worker.py", line 159, in worker
    state=Bot_Message.objects.get(current_state=user.state)
  File "/root/project/venv/lib/python3.10/site-packages/django/db/models/manager.py", line 87, in manager_method
    return getattr(self.get_queryset(), name)(*args, **kwargs)
  File "/root/project/venv/lib/python3.10/site-packages/django/db/models/query.py", line 649, in get
    raise self.model.DoesNotExist(
apps.bot.models.Bot_Message.DoesNotExist: Bot_Message matching query does not exist.
Traceback (most recent call last):
  File "/root/project/bot_bulder/bot_builder/apps/worker/management/commands/new_worker.py", line 115, in worker
    message_text = serialized_data['message']['text']
KeyError: 'text'

During handling of the above exception, another exception occurred:

Traceback (most recent call last):
  File "/root/project/bot_bulder/bot_builder/manage.py", line 22, in <module>
    main()
  File "/root/project/bot_bulder/bot_builder/manage.py", line 18, in main
    execute_from_command_line(sys.argv)
  File "/root/project/venv/lib/python3.10/site-packages/django/core/management/__init__.py", line 442, in execute_from_command_line
    utility.execute()
  File "/root/project/venv/lib/python3.10/site-packages/django/core/management/__init__.py", line 436, in execute
    self.fetch_command(subcommand).run_from_argv(self.argv)
  File "/root/project/venv/lib/python3.10/site-packages/django/core/management/__init__.py", line 275, in fetch_command
    klass = load_command_class(app_name, subcommand)
  File "/root/project/venv/lib/python3.10/site-packages/django/core/management/__init__.py", line 48, in load_command_class
    module = import_module("%s.management.commands.%s" % (app_name, name))
  File "/usr/lib/python3.10/importlib/__init__.py", line 126, in import_module
    return _bootstrap._gcd_import(name[level:], package, level)
  File "<frozen importlib._bootstrap>", line 1050, in _gcd_import
  File "<frozen importlib._bootstrap>", line 1027, in _find_and_load
  File "<frozen importlib._bootstrap>", line 1006, in _find_and_load_unlocked
  File "<frozen importlib._bootstrap>", line 688, in _load_unlocked
  File "<frozen importlib._bootstrap_external>", line 883, in exec_module
  File "<frozen importlib._bootstrap>", line 241, in _call_with_frames_removed
  File "/root/project/bot_bulder/bot_builder/apps/worker/management/commands/new_worker.py", line 13, in <module>
    class Command(BaseCommand):
  File "/root/project/bot_bulder/bot_builder/apps/worker/management/commands/new_worker.py", line 172, in Command
    worker(bot)
  File "/root/project/bot_bulder/bot_builder/apps/worker/management/commands/new_worker.py", line 159, in worker
    state=Bot_Message.objects.get(current_state=user.state)
  File "/root/project/venv/lib/python3.10/site-packages/django/db/models/manager.py", line 87, in manager_method
    return getattr(self.get_queryset(), name)(*args, **kwargs)
  File "/root/project/venv/lib/python3.10/site-packages/django/db/models/query.py", line 649, in get
    raise self.model.DoesNotExist(
apps.bot.models.Bot_Message.DoesNotExist: Bot_Message matching query does not exist.
Traceback (most recent call last):
  File "/root/project/bot_bulder/bot_builder/apps/worker/management/commands/new_worker.py", line 115, in worker
    message_text = serialized_data['message']['text']
KeyError: 'text'

During handling of the above exception, another exception occurred:

Traceback (most recent call last):
  File "/root/project/bot_bulder/bot_builder/manage.py", line 22, in <module>
    main()
  File "/root/project/bot_bulder/bot_builder/manage.py", line 18, in main
    execute_from_command_line(sys.argv)
  File "/root/project/venv/lib/python3.10/site-packages/django/core/management/__init__.py", line 442, in execute_from_command_line
    utility.execute()
  File "/root/project/venv/lib/python3.10/site-packages/django/core/management/__init__.py", line 436, in execute
    self.fetch_command(subcommand).run_from_argv(self.argv)
  File "/root/project/venv/lib/python3.10/site-packages/django/core/management/__init__.py", line 275, in fetch_command
    klass = load_command_class(app_name, subcommand)
  File "/root/project/venv/lib/python3.10/site-packages/django/core/management/__init__.py", line 48, in load_command_class
    module = import_module("%s.management.commands.%s" % (app_name, name))
  File "/usr/lib/python3.10/importlib/__init__.py", line 126, in import_module
    return _bootstrap._gcd_import(name[level:], package, level)
  File "<frozen importlib._bootstrap>", line 1050, in _gcd_import
  File "<frozen importlib._bootstrap>", line 1027, in _find_and_load
  File "<frozen importlib._bootstrap>", line 1006, in _find_and_load_unlocked
  File "<frozen importlib._bootstrap>", line 688, in _load_unlocked
  File "<frozen importlib._bootstrap_external>", line 883, in exec_module
  File "<frozen importlib._bootstrap>", line 241, in _call_with_frames_removed
  File "/root/project/bot_bulder/bot_builder/apps/worker/management/commands/new_worker.py", line 13, in <module>
    class Command(BaseCommand):
  File "/root/project/bot_bulder/bot_builder/apps/worker/management/commands/new_worker.py", line 172, in Command
    worker(bot)
  File "/root/project/bot_bulder/bot_builder/apps/worker/management/commands/new_worker.py", line 159, in worker
    state=Bot_Message.objects.get(current_state=user.state)
  File "/root/project/venv/lib/python3.10/site-packages/django/db/models/manager.py", line 87, in manager_method
    return getattr(self.get_queryset(), name)(*args, **kwargs)
  File "/root/project/venv/lib/python3.10/site-packages/django/db/models/query.py", line 649, in get
    raise self.model.DoesNotExist(
apps.bot.models.Bot_Message.DoesNotExist: Bot_Message matching query does not exist.
Traceback (most recent call last):
  File "/root/project/bot_bulder/bot_builder/apps/worker/management/commands/new_worker.py", line 115, in worker
    message_text = serialized_data['message']['text']
KeyError: 'text'

During handling of the above exception, another exception occurred:

Traceback (most recent call last):
  File "/root/project/bot_bulder/bot_builder/manage.py", line 22, in <module>
    main()
  File "/root/project/bot_bulder/bot_builder/manage.py", line 18, in main
    execute_from_command_line(sys.argv)
  File "/root/project/venv/lib/python3.10/site-packages/django/core/management/__init__.py", line 442, in execute_from_command_line
    utility.execute()
  File "/root/project/venv/lib/python3.10/site-packages/django/core/management/__init__.py", line 436, in execute
    self.fetch_command(subcommand).run_from_argv(self.argv)
  File "/root/project/venv/lib/python3.10/site-packages/django/core/management/__init__.py", line 275, in fetch_command
    klass = load_command_class(app_name, subcommand)
  File "/root/project/venv/lib/python3.10/site-packages/django/core/management/__init__.py", line 48, in load_command_class
    module = import_module("%s.management.commands.%s" % (app_name, name))
  File "/usr/lib/python3.10/importlib/__init__.py", line 126, in import_module
    return _bootstrap._gcd_import(name[level:], package, level)
  File "<frozen importlib._bootstrap>", line 1050, in _gcd_import
  File "<frozen importlib._bootstrap>", line 1027, in _find_and_load
  File "<frozen importlib._bootstrap>", line 1006, in _find_and_load_unlocked
  File "<frozen importlib._bootstrap>", line 688, in _load_unlocked
  File "<frozen importlib._bootstrap_external>", line 883, in exec_module
  File "<frozen importlib._bootstrap>", line 241, in _call_with_frames_removed
  File "/root/project/bot_bulder/bot_builder/apps/worker/management/commands/new_worker.py", line 13, in <module>
    class Command(BaseCommand):
  File "/root/project/bot_bulder/bot_builder/apps/worker/management/commands/new_worker.py", line 172, in Command
    worker(bot)
  File "/root/project/bot_bulder/bot_builder/apps/worker/management/commands/new_worker.py", line 159, in worker
    state=Bot_Message.objects.get(current_state=user.state)
  File "/root/project/venv/lib/python3.10/site-packages/django/db/models/manager.py", line 87, in manager_method
    return getattr(self.get_queryset(), name)(*args, **kwargs)
  File "/root/project/venv/lib/python3.10/site-packages/django/db/models/query.py", line 649, in get
    raise self.model.DoesNotExist(
apps.bot.models.Bot_Message.DoesNotExist: Bot_Message matching query does not exist.
Traceback (most recent call last):
  File "/root/project/bot_bulder/bot_builder/apps/worker/management/commands/new_worker.py", line 115, in worker
    message_text = serialized_data['message']['text']
KeyError: 'text'

During handling of the above exception, another exception occurred:

Traceback (most recent call last):
  File "/root/project/bot_bulder/bot_builder/manage.py", line 22, in <module>
    main()
  File "/root/project/bot_bulder/bot_builder/manage.py", line 18, in main
    execute_from_command_line(sys.argv)
  File "/root/project/venv/lib/python3.10/site-packages/django/core/management/__init__.py", line 442, in execute_from_command_line
    utility.execute()
  File "/root/project/venv/lib/python3.10/site-packages/django/core/management/__init__.py", line 436, in execute
    self.fetch_command(subcommand).run_from_argv(self.argv)
  File "/root/project/venv/lib/python3.10/site-packages/django/core/management/__init__.py", line 275, in fetch_command
    klass = load_command_class(app_name, subcommand)
  File "/root/project/venv/lib/python3.10/site-packages/django/core/management/__init__.py", line 48, in load_command_class
    module = import_module("%s.management.commands.%s" % (app_name, name))
  File "/usr/lib/python3.10/importlib/__init__.py", line 126, in import_module
    return _bootstrap._gcd_import(name[level:], package, level)
  File "<frozen importlib._bootstrap>", line 1050, in _gcd_import
  File "<frozen importlib._bootstrap>", line 1027, in _find_and_load
  File "<frozen importlib._bootstrap>", line 1006, in _find_and_load_unlocked
  File "<frozen importlib._bootstrap>", line 688, in _load_unlocked
  File "<frozen importlib._bootstrap_external>", line 883, in exec_module
  File "<frozen importlib._bootstrap>", line 241, in _call_with_frames_removed
  File "/root/project/bot_bulder/bot_builder/apps/worker/management/commands/new_worker.py", line 13, in <module>
    class Command(BaseCommand):
  File "/root/project/bot_bulder/bot_builder/apps/worker/management/commands/new_worker.py", line 172, in Command
    worker(bot)
  File "/root/project/bot_bulder/bot_builder/apps/worker/management/commands/new_worker.py", line 159, in worker
    state=Bot_Message.objects.get(current_state=user.state)
  File "/root/project/venv/lib/python3.10/site-packages/django/db/models/manager.py", line 87, in manager_method
    return getattr(self.get_queryset(), name)(*args, **kwargs)
  File "/root/project/venv/lib/python3.10/site-packages/django/db/models/query.py", line 649, in get
    raise self.model.DoesNotExist(
apps.bot.models.Bot_Message.DoesNotExist: Bot_Message matching query does not exist.
Traceback (most recent call last):
  File "/root/project/bot_bulder/bot_builder/apps/worker/management/commands/new_worker.py", line 115, in worker
    message_text = serialized_data['message']['text']
KeyError: 'text'

During handling of the above exception, another exception occurred:

Traceback (most recent call last):
  File "/root/project/bot_bulder/bot_builder/manage.py", line 22, in <module>
    main()
  File "/root/project/bot_bulder/bot_builder/manage.py", line 18, in main
    execute_from_command_line(sys.argv)
  File "/root/project/venv/lib/python3.10/site-packages/django/core/management/__init__.py", line 442, in execute_from_command_line
    utility.execute()
  File "/root/project/venv/lib/python3.10/site-packages/django/core/management/__init__.py", line 436, in execute
    self.fetch_command(subcommand).run_from_argv(self.argv)
  File "/root/project/venv/lib/python3.10/site-packages/django/core/management/__init__.py", line 275, in fetch_command
    klass = load_command_class(app_name, subcommand)
  File "/root/project/venv/lib/python3.10/site-packages/django/core/management/__init__.py", line 48, in load_command_class
    module = import_module("%s.management.commands.%s" % (app_name, name))
  File "/usr/lib/python3.10/importlib/__init__.py", line 126, in import_module
    return _bootstrap._gcd_import(name[level:], package, level)
  File "<frozen importlib._bootstrap>", line 1050, in _gcd_import
  File "<frozen importlib._bootstrap>", line 1027, in _find_and_load
  File "<frozen importlib._bootstrap>", line 1006, in _find_and_load_unlocked
  File "<frozen importlib._bootstrap>", line 688, in _load_unlocked
  File "<frozen importlib._bootstrap_external>", line 883, in exec_module
  File "<frozen importlib._bootstrap>", line 241, in _call_with_frames_removed
  File "/root/project/bot_bulder/bot_builder/apps/worker/management/commands/new_worker.py", line 13, in <module>
    class Command(BaseCommand):
  File "/root/project/bot_bulder/bot_builder/apps/worker/management/commands/new_worker.py", line 172, in Command
    worker(bot)
  File "/root/project/bot_bulder/bot_builder/apps/worker/management/commands/new_worker.py", line 159, in worker
    state=Bot_Message.objects.get(current_state=user.state)
  File "/root/project/venv/lib/python3.10/site-packages/django/db/models/manager.py", line 87, in manager_method
    return getattr(self.get_queryset(), name)(*args, **kwargs)
  File "/root/project/venv/lib/python3.10/site-packages/django/db/models/query.py", line 649, in get
    raise self.model.DoesNotExist(
apps.bot.models.Bot_Message.DoesNotExist: Bot_Message matching query does not exist.
Traceback (most recent call last):
  File "/root/project/bot_bulder/bot_builder/apps/worker/management/commands/new_worker.py", line 115, in worker
    message_text = serialized_data['message']['text']
KeyError: 'text'

During handling of the above exception, another exception occurred:

Traceback (most recent call last):
  File "/root/project/bot_bulder/bot_builder/manage.py", line 22, in <module>
    main()
  File "/root/project/bot_bulder/bot_builder/manage.py", line 18, in main
    execute_from_command_line(sys.argv)
  File "/root/project/venv/lib/python3.10/site-packages/django/core/management/__init__.py", line 442, in execute_from_command_line
    utility.execute()
  File "/root/project/venv/lib/python3.10/site-packages/django/core/management/__init__.py", line 436, in execute
    self.fetch_command(subcommand).run_from_argv(self.argv)
  File "/root/project/venv/lib/python3.10/site-packages/django/core/management/__init__.py", line 275, in fetch_command
    klass = load_command_class(app_name, subcommand)
  File "/root/project/venv/lib/python3.10/site-packages/django/core/management/__init__.py", line 48, in load_command_class
    module = import_module("%s.management.commands.%s" % (app_name, name))
  File "/usr/lib/python3.10/importlib/__init__.py", line 126, in import_module
    return _bootstrap._gcd_import(name[level:], package, level)
  File "<frozen importlib._bootstrap>", line 1050, in _gcd_import
  File "<frozen importlib._bootstrap>", line 1027, in _find_and_load
  File "<frozen importlib._bootstrap>", line 1006, in _find_and_load_unlocked
  File "<frozen importlib._bootstrap>", line 688, in _load_unlocked
  File "<frozen importlib._bootstrap_external>", line 883, in exec_module
  File "<frozen importlib._bootstrap>", line 241, in _call_with_frames_removed
  File "/root/project/bot_bulder/bot_builder/apps/worker/management/commands/new_worker.py", line 13, in <module>
    class Command(BaseCommand):
  File "/root/project/bot_bulder/bot_builder/apps/worker/management/commands/new_worker.py", line 172, in Command
    worker(bot)
  File "/root/project/bot_bulder/bot_builder/apps/worker/management/commands/new_worker.py", line 159, in worker
    state=Bot_Message.objects.get(current_state=user.state)
  File "/root/project/venv/lib/python3.10/site-packages/django/db/models/manager.py", line 87, in manager_method
    return getattr(self.get_queryset(), name)(*args, **kwargs)
  File "/root/project/venv/lib/python3.10/site-packages/django/db/models/query.py", line 649, in get
    raise self.model.DoesNotExist(
apps.bot.models.Bot_Message.DoesNotExist: Bot_Message matching query does not exist.
Traceback (most recent call last):
  File "/root/project/bot_bulder/bot_builder/apps/worker/management/commands/new_worker.py", line 115, in worker
    message_text = serialized_data['message']['text']
KeyError: 'text'

During handling of the above exception, another exception occurred:

Traceback (most recent call last):
  File "/root/project/bot_bulder/bot_builder/manage.py", line 22, in <module>
    main()
  File "/root/project/bot_bulder/bot_builder/manage.py", line 18, in main
    execute_from_command_line(sys.argv)
  File "/root/project/venv/lib/python3.10/site-packages/django/core/management/__init__.py", line 442, in execute_from_command_line
    utility.execute()
  File "/root/project/venv/lib/python3.10/site-packages/django/core/management/__init__.py", line 436, in execute
    self.fetch_command(subcommand).run_from_argv(self.argv)
  File "/root/project/venv/lib/python3.10/site-packages/django/core/management/__init__.py", line 275, in fetch_command
    klass = load_command_class(app_name, subcommand)
  File "/root/project/venv/lib/python3.10/site-packages/django/core/management/__init__.py", line 48, in load_command_class
    module = import_module("%s.management.commands.%s" % (app_name, name))
  File "/usr/lib/python3.10/importlib/__init__.py", line 126, in import_module
    return _bootstrap._gcd_import(name[level:], package, level)
  File "<frozen importlib._bootstrap>", line 1050, in _gcd_import
  File "<frozen importlib._bootstrap>", line 1027, in _find_and_load
  File "<frozen importlib._bootstrap>", line 1006, in _find_and_load_unlocked
  File "<frozen importlib._bootstrap>", line 688, in _load_unlocked
  File "<frozen importlib._bootstrap_external>", line 883, in exec_module
  File "<frozen importlib._bootstrap>", line 241, in _call_with_frames_removed
  File "/root/project/bot_bulder/bot_builder/apps/worker/management/commands/new_worker.py", line 13, in <module>
    class Command(BaseCommand):
  File "/root/project/bot_bulder/bot_builder/apps/worker/management/commands/new_worker.py", line 172, in Command
    worker(bot)
  File "/root/project/bot_bulder/bot_builder/apps/worker/management/commands/new_worker.py", line 159, in worker
    state=Bot_Message.objects.get(current_state=user.state)
  File "/root/project/venv/lib/python3.10/site-packages/django/db/models/manager.py", line 87, in manager_method
    return getattr(self.get_queryset(), name)(*args, **kwargs)
  File "/root/project/venv/lib/python3.10/site-packages/django/db/models/query.py", line 649, in get
    raise self.model.DoesNotExist(
apps.bot.models.Bot_Message.DoesNotExist: Bot_Message matching query does not exist.
